Workbook

Sheet How It Works
B1: Propto Issue Taxonomy v3 - object + problem
B2: The category is decided by WHAT is faulty (the object) and WHAT is wrong with it (the problem). WHERE it is (flat, lobby, clubhouse, B wing) is only recorded, never used to decide the category.
B3: "AC not cooling in flat", "AC not cooling in lobby" and "Clubhouse AC not cooling" all become the same line: AC not cooling -> AC & Ventilation -> AC AMC Vendor.
B4: 483 generic issue lines, 151 objects, 42 problems, 11 safety overrides, 10 location groups.
B6: How a message is read
B7: 1. Clean the text: lower-case, symbols become spaces. Find every word / phrase from the Objects, Problems, Safety and Locations tabs (a plural s/es also matches). A longer phrase wins over a shorter one inside it: "fire extinguisher" is an object, so "fire" inside it is not treated as a fire.
B8: 2. Safety override: if any Safety word is present (fire, smoke, sparking, gas leak, trapped, theft, injury, snake, flooding...), that line wins straight away.
B9: 3. Object + problem: look up every object-problem pair on the Line Map tab. If several pairs match: Subject objects (pests, animals, garbage, deliveries) beat Equipment, which beats Places / people; then the object nearest the problem word wins; then category priority.
B10: 4. Problem only: no object with a matching pair, but the problem has its own line (leakage -> Plumbing, seepage -> Seepage, crack -> Civil, noise -> Noise & Disputes, dirty -> Housekeeping, blocked -> Drainage).
B11: 5. Object only: an object but no problem word -> that object's default line ("Pigeons on my AC" -> Pigeon / bird nuisance).
B12: 6. Nothing recognised -> General / Unclassified -> send to the AI step.
B13: Severity, SLA, vendor and action come from the chosen line. Location (flat, lobby, wing...) is attached to the ticket only.
B15: Examples
B16: AC not cooling in lobby | C16: AC + not cooling | D16: AC not cooling -> AC & Ventilation (location: Lobby)
B17: Leakage issue in my bathroom | C17: leakage (no object) | D17: Leakage -> Plumbing & Leakage (location: Flat)
B18: AC leaking water in corridor | C18: AC + leaking | D18: AC water leaking -> AC & Ventilation, not Plumbing
B19: Light not working in gym | C19: light + not working | D19: Light not working -> Electrical (gym is a place)
B20: Gym closed on Sunday | C20: gym + closed | D20: Gym closed / timing issue -> Amenities
B21: No light in B wing | C21: light + no | D21: No electricity / power cut -> Electrical
B22: pani nahi aa raha | C22: pani + nahi aa | D22: Water not coming / no water -> Water Supply
B23: Switch board sparking | C23: Safety: sparking | D23: Sparking / short circuit / shock -> Electrical, Critical
B25: Editing
B26: - New word for an existing object or problem: add it to that row's word list (comma separated). Each word may appear only once across all tabs.
B27: - New object: add a row on Objects, then add its object-problem pairs on Line Map. Pick the lines from the Issue Lines tab or add a new line there.
B28: - Vendor per category: Categories tab. SLA per severity: table below. Blue text = inputs.
B30: Severity -> SLA / action
B31: Severity | C31: Target SLA | D31: Propto Action
B32: Critical | C32: 0-2 hours | D32: Ticket + Manager Alert
B33: High | C33: 4-8 hours | D33: Ticket + Manager Alert
B34: Medium | C34: 1-2 days | D34: Ticket
B35: Low | C35: 3-5 days | D35: Ticket

Sheet Issue Lines
A1: Issue ID | B1: Issue Line | C1: Category | D1: Severity | E1: Target SLA | F1: Default Vendor / Owner | G1: Propto Action | H1: Objects | I1: Problems | J1: Short Label (1-3 words)
A2: L001 | B2: Medical emergency / injury | C2: Medical & Emergency | D2: Critical | E2: =INDEX('How It Works'!$C$32:$C$35,MATCH(D2,'How It Works'!$B$32:$B$35,0)) -> 0-2 hours | F2: =INDEX(Categories!$E$2:$E$29,MATCH(C2,Categories!$B$2:$B$29,0)) -> Society Manager | G2: =INDEX('How It Works'!$D$32:$D$35,MATCH(D2,'How It Works'!$B$32:$B$35,0)) -> Ticket + Manager Alert | H2: - | I2: Safety override | J2: Medical emergency
A3: L474 | B3: First aid / medical equipment missing | C3: Medical & Emergency | D3: High | E3: =INDEX('How It Works'!$C$32:$C$35,MATCH(D3,'How It Works'!$B$32:$B$35,0)) -> 4-8 hours | F3: =INDEX(Categories!$E$2:$E$29,MATCH(C3,Categories!$B$2:$B$29,0)) -> Society Manager | G3: =INDEX('How It Works'!$D$32:$D$35,MATCH(D3,'How It Works'!$B$32:$B$35,0)) -> Ticket + Manager Alert | H3: First aid kit | I3: Any problem | J3: First-aid kit missing
A4: L002 | B4: Fire / smoke | C4: Fire Safety | D4: Critical | E4: =INDEX('How It Works'!$C$32:$C$35,MATCH(D4,'How It Works'!$B$32:$B$35,0)) -> 0-2 hours | F4: =INDEX(Categories!$E$2:$E$29,MATCH(C4,Categories!$B$2:$B$29,0)) -> Fire Safety Vendor | G4: =INDEX('How It Works'!$D$32:$D$35,MATCH(D4,'How It Works'!$B$32:$B$35,0)) -> Ticket + Manager Alert | H4: - | I4: Safety override | J4: Fire or smoke
A5: L455 | B5: Fire extinguisher issue | C5: Fire Safety | D5: Medium | E5: =INDEX('How It Works'!$C$32:$C$35,MATCH(D5,'How It Works'!$B$32:$B$35,0)) -> 1-2 days | F5: =INDEX(Categories!$E$2:$E$29,MATCH(C5,Categories!$B$2:$B$29,0)) -> Fire Safety Vendor | G5: =INDEX('How It Works'!$D$32:$D$35,MATCH(D5,'How It Works'!$B$32:$B$35,0)) -> Ticket | H5: Fire extinguisher | I5: (no problem word) | J5: Extinguisher issue
A6: L456 | B6: Fire extinguisher expired / refill due | C6: Fire Safety | D6: Medium | E6: =INDEX('How It Works'!$C$32:$C$35,MATCH(D6,'How It Works'!$B$32:$B$35,0)) -> 1-2 days | F6: =INDEX(Categories!$E$2:$E$29,MATCH(C6,Categories!$B$2:$B$29,0)) -> Fire Safety Vendor | G6: =INDEX('How It Works'!$D$32:$D$35,MATCH(D6,'How It Works'!$B$32:$B$35,0)) -> Ticket | H6: Fire extinguisher | I6: Expired / service due | J6: Extinguisher refill due
A7: L457 | B7: Fire extinguisher missing | C7: Fire Safety | D7: Low | E7: =INDEX('How It Works'!$C$32:$C$35,MATCH(D7,'How It Works'!$B$32:$B$35,0)) -> 3-5 days | F7: =INDEX(Categories!$E$2:$E$29,MATCH(C7,Categories!$B$2:$B$29,0)) -> Fire Safety Vendor | G7: =INDEX('How It Works'!$D$32:$D$35,MATCH(D7,'How It Works'!$B$32:$B$35,0)) -> Ticket | H7: Fire extinguisher | I7: Missing | J7: Extinguisher missing
A8: L458 | B8: Fire extinguisher broken / damaged | C8: Fire Safety | D8: Medium | E8: =INDEX('How It Works'!$C$32:$C$35,MATCH(D8,'How It Works'!$B$32:$B$35,0)) -> 1-2 days | F8: =INDEX(Categories!$E$2:$E$29,MATCH(C8,Categories!$B$2:$B$29,0)) -> Fire Safety Vendor | G8: =INDEX('How It Works'!$D$32:$D$35,MATCH(D8,'How It Works'!$B$32:$B$35,0)) -> Ticket | H8: Fire extinguisher | I8: Broken / damaged | J8: Extinguisher damaged
A9: L459 | B9: Fire extinguisher not working | C9: Fire Safety | D9: Medium | E9: =INDEX('How It Works'!$C$32:$C$35,MATCH(D9,'How It Works'!$B$32:$B$35,0)) -> 1-2 days | F9: =INDEX(Categories!$E$2:$E$29,MATCH(C9,Categories!$B$2:$B$29,0)) -> Fire Safety Vendor | G9: =INDEX('How It Works'!$D$32:$D$35,MATCH(D9,'How It Works'!$B$32:$B$35,0)) -> Ticket | H9: Fire extinguisher | I9: Not working | J9: Extinguisher not working
A10: L460 | B10: Fire alarm / detector - other issue | C10: Fire Safety | D10: High | E10: =INDEX('How It Works'!$C$32:$C$35,MATCH(D10,'How It Works'!$B$32:$B$35,0)) -> 4-8 hours | F10: =INDEX(Categories!$E$2:$E$29,MATCH(C10,Categories!$B$2:$B$29,0)) -> Fire Safety Vendor | G10: =INDEX('How It Works'!$D$32:$D$35,MATCH(D10,'How It Works'!$B$32:$B$35,0)) -> Ticket + Manager Alert | H10: Fire alarm / detector | I10: (no problem word) | J10: Fire alarm issue
A11: L461 | B11: Fire alarm / detector not working | C11: Fire Safety | D11: High | E11: =INDEX('How It Works'!$C$32:$C$35,MATCH(D11,'How It Works'!$B$32:$B$35,0)) -> 4-8 hours | F11: =INDEX(Categories!$E$2:$E$29,MATCH(C11,Categories!$B$2:$B$29,0)) -> Fire Safety Vendor | G11: =INDEX('How It Works'!$D$32:$D$35,MATCH(D11,'How It Works'!$B$32:$B$35,0)) -> Ticket + Manager Alert | H11: Fire alarm / detector | I11: Not working | J11: Fire alarm faulty
A12: L462 | B12: Fire alarm ringing / false alarm | C12: Fire Safety | D12: High | E12: =INDEX('How It Works'!$C$32:$C$35,MATCH(D12,'How It Works'!$B$32:$B$35,0)) -> 4-8 hours | F12: =INDEX(Categories!$E$2:$E$29,MATCH(C12,Categories!$B$2:$B$29,0)) -> Fire Safety Vendor | G12: =INDEX('How It Works'!$D$32:$D$35,MATCH(D12,'How It Works'!$B$32:$B$35,0)) -> Ticket + Manager Alert | H12: Fire alarm / detector | I12: Noise | J12: False fire alarm
A13: L463 | B13: Fire alarm / detector broken / damaged | C13: Fire Safety | D13: High | E13: =INDEX('How It Works'!$C$32:$C$35,MATCH(D13,'How It Works'!$B$32:$B$35,0)) -> 4-8 hours | F13: =INDEX(Categories!$E$2:$E$29,MATCH(C13,Categories!$B$2:$B$29,0)) -> Fire Safety Vendor | G13: =INDEX('How It Works'!$D$32:$D$35,MATCH(D13,'How It Works'!$B$32:$B$35,0)) -> Ticket + Manager Alert | H13: Fire alarm / detector | I13: Broken / damaged | J13: Fire alarm damaged
... A484: L483 | B484: Complaint not responded to | C484: Society Admin & Documents | D484: Low | E484: =INDEX('How It Works'!$C$32:$C$35,MATCH(D484,'How It Works'!$B$32:$B$35,0)) -> 3-5 days | F484: =INDEX(Categories!$E$2:$E$29,MATCH(C484,Categories!$B$2:$B$29,0)) -> Society Manager / Committee | G484: =INDEX('How It Works'!$D$32:$D$35,MATCH(D484,'How It Works'!$B$32:$B$35,0)) -> Ticket | H484: - | I484: Not responding | J484: Complaint not addressed

Sheet Short Labels
A1: Category | B1: Short Label | C1: Issue ID | D1: Full Issue Line | E1: Severity
A2: Medical & Emergency | B2: Medical emergency | C2: L001 | D2: Medical emergency / injury | E2: Critical
A3: Medical & Emergency | B3: First-aid kit missing | C3: L474 | D3: First aid / medical equipment missing | E3: High
A4: Fire Safety | B4: Fire or smoke | C4: L002 | D4: Fire / smoke | E4: Critical
A5: Fire Safety | B5: Extinguisher issue | C5: L455 | D5: Fire extinguisher issue | E5: Medium
A6: Fire Safety | B6: Extinguisher refill due | C6: L456 | D6: Fire extinguisher expired / refill due | E6: Medium
A7: Fire Safety | B7: Extinguisher missing | C7: L457 | D7: Fire extinguisher missing | E7: Low
A8: Fire Safety | B8: Extinguisher damaged | C8: L458 | D8: Fire extinguisher broken / damaged | E8: Medium
A9: Fire Safety | B9: Extinguisher not working | C9: L459 | D9: Fire extinguisher not working | E9: Medium
A10: Fire Safety | B10: Fire alarm issue | C10: L460 | D10: Fire alarm / detector - other issue | E10: High
A11: Fire Safety | B11: Fire alarm faulty | C11: L461 | D11: Fire alarm / detector not working | E11: High
A12: Fire Safety | B12: False fire alarm | C12: L462 | D12: Fire alarm ringing / false alarm | E12: High
... A484: Society Admin & Documents | B484: Complaint not addressed | C484: L483 | D484: Complaint not responded to | E484: Low

Sheet Label Watch-outs
A1: Confusable labels | B1: Why it can mis-map | C1: Suggestion
A2: Ceiling leak (Plumbing) vs Ceiling seepage (Seepage) | B2: Residents use 'leak' and 'seepage' interchangeably for the same wet ceiling. | C2: Treat dripping water as Ceiling leak and damp patches as Ceiling seepage, or merge both into Seepage.
A3: Water leak (Plumbing) vs Water through wall (Seepage) | B3: 'Water leaking through wall' and 'water leakage' are both leaks. | C3: Keep the wall label in Seepage; the label must contain 'wall' for it to go there.
A4: Pipe blocked (Plumbing) vs Drain choked / Sewage line choked (Drainage) | B4: Blocked pipe usually means a drain pipe. | C4: Consider moving Pipe blocked to Drainage & Sewage.
A5: Toilet leak (Plumbing) vs Toilet choked (Drainage) | B5: Same object, two categories. | C5: Fine as is, but the vendor is often the same plumber; check routing.
A6: Power tripping vs MCB tripping vs Tripping (unspecified) | B6: Three near-identical lines, all Electrical/High. | C6: Merge into one 'Power tripping' line.
A7: Power cut vs Grid outage (MSEDCL) | B7: Residents can't tell a society fault from an MSEDCL outage. | C7: Keep one resident-facing label (Power cut); let the manager re-tag as Grid outage.
A8: Solar heater faulty (DG & Solar) vs Geyser not heating (Electrical) | B8: Resident just says 'no hot water'. | C8: Labels now name the device; 'no hot water' with no device should go to the AI step or a default.
A9: Solar heater leak / Geyser leak (Plumbing) | B9: Other faults on the same device sit in DG/Solar or Electrical. | C9: Intentional if a plumber fixes leaks; otherwise move them next to the device.
A10: Gas reading wrong (Gas Supply) vs Electric/Water reading wrong (Billing) | B10: Same problem type, different categories. | C10: Move Gas reading wrong (and Gas bill query) to Billing & Accounts, or the other two to their supply categories.
A11: Sports court dirty (Amenities) / Garden dirty (Garden) | B11: Every other 'X dirty' common-area line goes to Housekeeping. | C11: Move to Housekeeping & Cleaning for consistency.
A12: Car not washed vs Car poorly washed | B12: Near-duplicates in Parking. | C12: Merge into one line.
... A21: Pet waste (Animals) vs Common area dirty (Housekeeping) | B21: Pet waste is also a cleaning task. | C21: Keep in Animals for rule enforcement; cleaning follows from the ticket.

Sheet Categories
A1: Priority | B1: Category | C1: What belongs here | D1: Default Severity | E1: Default Vendor / Owner | F1: Issue lines
A2: 1 | B2: Medical & Emergency | C2: Injury, medical emergency, ambulance | D2: Critical | E2: Society Manager | F2: =COUNTIF('Issue Lines'!$C:$C,B2) -> 2
A3: 2 | B3: Fire Safety | C3: Fire, smoke, extinguishers, alarms, hydrants, fire exits | D3: High | E3: Fire Safety Vendor | F3: =COUNTIF('Issue Lines'!$C:$C,B3) -> 20
A4: 3 | B4: Gas Supply | C4: Piped gas / LPG supply, gas leak | D4: High | E4: Gas Agency (MGL/PNG) | F4: =COUNTIF('Issue Lines'!$C:$C,B4) -> 9
A5: 4 | B5: Lift | C5: Lift / elevator | D5: High | E5: Lift AMC Vendor | F5: =COUNTIF('Issue Lines'!$C:$C,B5) -> 17
A6: 5 | B6: Swimming Pool | C6: Pool water, pool equipment, lifeguard | D6: Medium | E6: Pool AMC Vendor | F6: =COUNTIF('Issue Lines'!$C:$C,B6) -> 11
A7: 6 | B7: DG, Inverter & Solar | C7: Generator, inverter, solar panels, solar hot water | D7: High | E7: DG / Solar AMC Vendor | F7: =COUNTIF('Issue Lines'!$C:$C,B7) -> 13
A8: 7 | B8: AC & Ventilation | C8: AC units, exhaust fans, ventilation | D8: Medium | E8: AC AMC Vendor | F8: =COUNTIF('Issue Lines'!$C:$C,B8) -> 16
A9: 8 | B9: Electrical | C9: Power supply, lights, fans, switches, wiring, MCB, meters | D9: High | E9: Electrician | F9: =COUNTIF('Issue Lines'!$C:$C,B9) -> 40
A10: 9 | B10: Water Supply | C10: Water supply, pressure, tanks, pumps, tankers, RO | D10: High | E10: Plumber / Water Vendor | F10: =COUNTIF('Issue Lines'!$C:$C,B10) -> 27
A11: 10 | B11: Plumbing & Leakage | C11: Leakage, taps, pipes, flush, toilets, basins, valves | D11: High | E11: Plumber | F11: =COUNTIF('Issue Lines'!$C:$C,B11) -> 27
A12: 11 | B12: Drainage & Sewage | C12: Drains, gutters, chokes, sewage, STP, flooding | D12: High | E12: Plumber / STP Operator | F12: =COUNTIF('Issue Lines'!$C:$C,B12) -> 18
A13: 12 | B13: Seepage & Waterproofing | C13: Seepage, dampness, fungus, rain water entering | D13: Medium | E13: Waterproofing Vendor | F13: =COUNTIF('Issue Lines'!$C:$C,B13) -> 8
... A29: 99 | B29: General / Unclassified | C29: Nothing recognised - send to AI step | D29: Low | E29: Society Manager | F29: =COUNTIF('Issue Lines'!$C:$C,B29) -> 0
B31: Total issue lines | F31: =SUM(F2:F29) -> 483

Sheet Objects
A1: Object | B1: Category | C1: Type | D1: Words that mean this object | E1: Shortcut phrases (phrase -> problem) | F1: Line if no problem word | G1: Default Severity | H1: Issue ID
A2: First aid kit | B2: Medical & Emergency | C2: Equipment / structure | D2: first aid, first aid kit, aed, stretcher, wheelchair | F2: First aid / medical equipment missing | G2: High | H2: L474
A3: Fire NOC / drill | B3: Fire Safety | C3: Equipment / structure | D3: fire noc, fire audit, fire drill, mock drill, fire safety, fire risk, fire hazard, fire evacuation, evacuation, fire tender, fire brigade | F3: Fire safety concern / NOC / drill due | G3: Medium | H3: L473
A4: Fire alarm / detector | B4: Fire Safety | C4: Equipment / structure | D4: fire alarm, smoke detector, smoke detectors, smoke alarm, fire panel, alarm | F4: Fire alarm / detector - other issue | G4: High | H4: L460
A5: Fire exit | B5: Fire Safety | C5: Equipment / structure | D5: fire exit, emergency exit, exit door, fire door, refuge area | F5: Fire exit - other issue | G5: High | H5: L469
A6: Fire extinguisher | B6: Fire Safety | C6: Equipment / structure | D6: fire extinguisher, extinguisher, extinguishers, fire extinguishers | F6: Fire extinguisher issue | G6: Medium | H6: L455
A7: Hydrant / sprinkler | B7: Fire Safety | C7: Equipment / structure | D7: hydrant, fire hydrant, sprinkler, sprinklers, hose reel, fire hose, fire pump, fire line, fire tank, fire fighting system | F7: Hydrant / sprinkler - other issue | G7: High | H7: L464
A8: Gas bill | B8: Gas Supply | C8: Equipment / structure | D8: gas bill, png bill, mgl bill | F8: Gas bill query | G8: Low | H8: L426
A9: Gas meter | B9: Gas Supply | C9: Equipment / structure | D9: gas meter, png meter | F9: Gas meter - other issue | G9: Medium | H9: L451
A10: Gas supply | B10: Gas Supply | C10: Equipment / structure | D10: gas, png, lpg, piped gas, gas supply, gas pipeline, gas line, mgl, mahanagar gas, mngl, cylinder, gas cylinder, gas stove | F10: Gas supply - other issue | G10: High | H10: L447
A11: Lift | B11: Lift | C11: Equipment / structure | D11: lift, elevator, service lift, passenger lift, lift car, lift ki light, lift light, lift fan | F11: Lift - other issue | G11: High | H11: L012
A12: Lift alarm / phone | B12: Lift | C12: Equipment / structure | D12: lift alarm, lift phone, lift intercom, lift emergency button, ard | F12: Lift alarm / phone - other issue | G12: High | H12: L027
A13: Lift button / display | B13: Lift | C13: Equipment / structure | D13: lift button, lift buttons, lift panel, lift display | F13: Lift button / display - other issue | G13: Medium | H13: L024
... A27: Electric meter | B27: Electrical | C27: Equipment / structure | D27: meter, electric meter, electricity meter, light meter | F27: Electric meter - other issue | G27: Medium | H27: L055
A28: Electricity | B28: Electrical | C28: Equipment / structure | D28: electricity, power, bijli, current, power supply, electricity supply | E28: outage -> No supply / not coming; load shedding -> No supply / not coming; blackout -> No supply / not coming | F28: Power supply issue | G28: Critical | H28: L029
A29: Fan | B29: Electrical | C29: Equipment / structure | D29: fan, fans, ceiling fan | F29: Fan - other issue | G29: Medium | H29: L038
A30: Geyser | B30: Electrical | C30: Equipment / structure | D30: geyser, water heater | F30: Geyser - other issue | G30: Medium | H30: L059
A31: Light | B31: Electrical | C31: Equipment / structure | D31: light, lights, bulb, bulbs, tube light, tubelight, lamp, street light, emergency light, led, lighting | F31: Light not working | G31: High | H31: L033
A32: MCB / DB | B32: Electrical | C32: Equipment / structure | D32: mcb, fuse, db, db box, distribution board, electric panel, panel, rccb, elcb | F32: MCB / DB - other issue | G32: High | H32: L051
A33: Switch / socket | B33: Electrical | C33: Equipment / structure | D33: switch, switches, socket, sockets, switchboard, switch board, plug, plug point | F33: Switch / socket - other issue | G33: Medium | H33: L043
A34: Transformer / MSEDCL | B34: Electrical | C34: Equipment / structure | D34: transformer, msedcl, mseb, adani electricity, tata power, substation | F34: Transformer / MSEDCL - other issue | G34: High | H34: L067
A35: Wiring | B35: Electrical | C35: Equipment / structure | D35: wire, wires, wiring, electric wire, electrical wire | F35: Wiring - other issue | G35: High | H35: L047
A36: Borewell | B36: Water Supply | C36: Equipment / structure | D36: borewell, bore well, bore | F36: Borewell - other issue | G36: Medium | H36: L126
A37: RO / water purifier | B37: Water Supply | C37: Equipment / structure | D37: ro, ro plant, purifier, water purifier, water filter, water cooler, filter | F37: RO / water purifier - other issue | G37: Medium | H37: L119
A38: Water | B38: Water Supply | C38: Equipment / structure | D38: water, pani, paani, water supply, municipal water, corporation water, vvcmc water, drinking water, nal ka pani | E38: yellow water -> Dirty / not cleaned; black water -> Dirty / not cleaned; brown water -> Dirty / not cleaned; dirty water -> Dirty / not cleaned; muddy water -> Dirty / not cleaned | F38: Water supply issue | G38: High | H38: L099
A39: Water meter | B39: Water Supply | C39: Equipment / structure | D39: water meter | F39: Water meter - other issue | G39: Low | H39: L123
A40: Water pump / motor | B40: Water Supply | C40: Equipment / structure | D40: motor, pump, water pump, booster pump, pump motor, motor pump | F40: Water pump / motor - other issue | G40: High | H40: L112
A41: Water tank | B41: Water Supply | C41: Equipment / structure | D41: water tank, tank, tanks, overhead tank, underground tank, sump, tanki | E41: tank cleaning -> Dirty / not cleaned | F41: Water tank - other issue | G41: High | H41: L107
A42: Water tanker | B42: Water Supply | C42: Equipment / structure | D42: tanker, water tanker | F42: Water tanker - other issue | G42: High | H42: L116
A43: Pipe | B43: Plumbing & Leakage | C43: Equipment / structure | D43: pipe, pipes, pipeline, water line, inlet pipe, outlet pipe, concealed pipe | E43: pipe burst -> Broken / damaged | F43: Pipe - other issue | G43: High | H43: L134
A44: Tap / shower | B44: Plumbing & Leakage | C44: Equipment / structure | D44: tap, taps, nal, faucet, mixer, bib cock, health faucet, jet spray, shower | F44: Tap / shower - other issue | G44: Medium | H44: L129
A45: Toilet / flush | B45: Plumbing & Leakage | C45: Equipment / structure | D45: flush, flush tank, cistern, commode, toilet, toilets, wc, toilet seat, washroom, toilet flush | F45: Toilet / flush - other issue | G45: High | H45: L138
A46: Valve | B46: Plumbing & Leakage | C46: Equipment / structure | D46: valve, valves, main valve, stop cock, stopcock | F46: Valve - other issue | G46: Medium | H46: L147
A47: Wash basin / sink | B47: Plumbing & Leakage | C47: Equipment / structure | D47: wash basin, washbasin, basin, sink, kitchen sink | F47: Wash basin / sink - other issue | G47: Medium | H47: L143
A48: Drain | B48: Drainage & Sewage | C48: Equipment / structure | D48: drain, drains, drainage, nali, nala, gutter, gully trap, nahani, floor trap, chamber, manhole, storm drain, drain pipe, soil pipe, rainwater pipe, rain pipe | F48: Drain blocked / choked | G48: High | H48: L151
A49: STP | B49: Drainage & Sewage | C49: Equipment / structure | D49: stp, sewage plant, sewage treatment plant | F49: STP - other issue | G49: Medium | H49: L161
A50: Sewage | B50: Drainage & Sewage | C50: Equipment / structure | D50: sewage, sewer, sewage line, sewerage, septic tank, sewage water | E50: backflow -> Overflowing; back flow -> Overflowing | F50: Sewage overflow / backflow | G50: High | H50: L157
A51: Rain water | B51: Seepage & Waterproofing | C51: Subject | D51: rain, rains, rainwater, rain water, baarish, barish | F51: Rain water entering | G51: Medium | H51: L105
A52: Waterproofing | B52: Seepage & Waterproofing | C52: Equipment / structure | D52: waterproofing, water proofing | F52: Waterproofing needed | G52: Medium | H52: L165
A53: Benches / furniture | B53: Civil & Structural | C53: Equipment / structure | D53: bench, benches, furniture, chair, chairs, sofa | F53: Benches / furniture - other issue | G53: Low | H53: L221
...

Sheet Line Map
A1: Object | B1: Problem | C1: Issue ID | D1: Issue Line | E1: Category
A2: First aid kit | B2: Not working | C2: L474 | D2: First aid / medical equipment missing | E2: Medical & Emergency
A3: First aid kit | B3: No supply / not coming | C3: L474 | D3: First aid / medical equipment missing | E3: Medical & Emergency
A4: First aid kit | B4: Broken / damaged | C4: L474 | D4: First aid / medical equipment missing | E4: Medical & Emergency
A5: First aid kit | B5: Noise | C5: L474 | D5: First aid / medical equipment missing | E5: Medical & Emergency
A6: First aid kit | B6: Not cooling | C6: L474 | D6: First aid / medical equipment missing | E6: Medical & Emergency
A7: First aid kit | B7: Leaking | C7: L474 | D7: First aid / medical equipment missing | E7: Medical & Emergency
A8: First aid kit | B8: Seepage / dampness | C8: L474 | D8: First aid / medical equipment missing | E8: Medical & Emergency
A9: First aid kit | B9: Crack | C9: L474 | D9: First aid / medical equipment missing | E9: Medical & Emergency
A10: First aid kit | B10: Falling | C10: L474 | D10: First aid / medical equipment missing | E10: Medical & Emergency
A11: First aid kit | B11: Bad smell | C11: L474 | D11: First aid / medical equipment missing | E11: Medical & Emergency
A12: First aid kit | B12: Flickering | C12: L474 | D12: First aid / medical equipment missing | E12: Medical & Emergency
... A2283: Tenant | B2283: Pending / requested | C2283: L436 | D2283: Tenant registration / verification | E2283: Society Admin & Documents

Sheet Problems
A1: Code | B1: Problem | C1: Words that mean this problem | D1: Line if no object found | E1: Category if no object found | F1: Issue ID
A2: NW | B2: Not working | C2: not working, not work, kharab, band, bandh, off, dead, down, faulty, fault, out of order, stopped, not functioning, nahi chal, nahi chalta, nahi chal raha, not starting, not started, not start, failed, failure, problem, issue, complaint, kaam nahi, not charging, defective, malfunction, chalu nahi | D2: (needs an object) | E2: -
A3: NS | B3: No supply / not coming | C3: no, not coming, no supply, nahi aa, nahi aa raha, nahi aata, nahi hai, nahi, not available, cut, gone, gayi, gaya, chali gayi, chala gaya, khali, empty | D3: (needs an object) | E3: -
A4: BR | B4: Broken / damaged | C4: broken, broke, damaged, damage, damaging, toota, tuta, tut gaya, toot gaya, burst, torn, fata, tod diya | D4: (needs an object) | E4: -
A5: NZ | B5: Noise | C5: noise, noisy, sound, awaaz, aawaz, vibration, vibrating, rattling, shor, loud, making noise | D5: Noise disturbance | E5: Noise, Nuisance & Disputes | F5: L475
A6: NC | B6: Not cooling | C6: not cooling, no cooling, cooling, thanda nahi, less cooling, warm air, hot air, cooling nahi | D6: (needs an object) | E6: -
A7: LK | B7: Leaking | C7: leak, leaking, leakage, leaked, dripping, drip, tapak, tapakna, tapak raha, tapakta, oozing | D7: Leakage (source not mentioned) | E7: Plumbing & Leakage | F7: L476
A8: SP | B8: Seepage / dampness | C8: seepage, seep, seeping, damp, dampness, moisture, fungus, fungal, mould, mold, seelan, silan, water stain, efflorescence | D8: Seepage / dampness | E8: Seepage & Waterproofing | F8: L477
A9: CR | B9: Crack | C9: crack, cracked, cracking, darar | D9: Crack (location not clear) | E9: Civil & Structural | F9: L478
A10: FA | B10: Falling | C10: falling, fell, fallen, gir gaya, gira, girna, gir raha | D10: Something falling / fallen | E10: Civil & Structural | F10: L479
A11: SM | B11: Bad smell | C11: smell, smelling, odour, odor, stink, stinking, badbu, foul smell, bad smell, smelly | D11: (needs an object) | E11: -
A12: FL | B12: Flickering | C12: flickering, flicker, blinking, dim | D12: (needs an object) | E12: -
A13: TR | B13: Tripping | C13: tripping, trip, tripped | D13: MCB / power tripping | E13: Electrical | F13: L480
A14: ST | B14: Stuck / not opening or closing | C14: stuck, jammed, jam, atak, atka, atak gaya, not opening, not closing, not close, not open, hard to open, not locking | D14: (needs an object) | E14: -
A15: LP | B15: Low pressure | C15: low pressure, less pressure, pressure low, kam pressure, low flow, slow flow, kam | D15: Low water pressure | E15: Water Supply | F15: L101
A16: DT | B16: Dirty / not cleaned | C16: dirty, ganda, gandi, unclean, not cleaned, not clean, muddy, contaminated, cleaning, safai nahi, dust, dusty, stain, unhygienic | D16: Common area dirty / not cleaned | E16: Housekeeping & Cleaning | F16: L481
A17: OF | B17: Overflowing | C17: overflow, overflowing, overflowed, bhar gaya, full | D17: (needs an object) | E17: -
A18: BL | B18: Blocked / choked | C18: blocked, blockage, choke, choked, chokeup, choke up, clogged, blocking | D18: Drain blocked / choked | E18: Drainage & Sewage | F18: L151
A19: MS | B19: Missing | C19: missing, gayab, removed, not there, lost | D19: (needs an object) | E19: -
A20: LS | B20: Loose / hanging | C20: loose, hanging, dheela, dangling, came off, coming off, detached, uprooted | D20: (needs an object) | E20: -
A21: RS | B21: Rusted | C21: rust, rusted, rusty, corroded, corrosion, jang | D21: (needs an object) | E21: -
A22: PE | B22: Peeling / faded | C22: peeling, peel, peeled, flaking, faded, fading | D22: (needs an object) | E22: -
A23: EX | B23: Expired / service due | C23: expired, expiry, overdue, refill, service due, servicing, not serviced, amc, maintenance due, renewal | D23: (needs an object) | E23: -
A24: HT | B24: Not heating | C24: not heating, not hot, cold water, garam nahi, no heating | D24: (needs an object) | E24: -
A25: SL | B25: Slow / no signal | C25: slow, no signal, no network, disconnect, disconnecting, buffering, speed, weak signal, signal, range | D25: (needs an object) | E25: -
A26: VF | B26: Voltage fluctuation | C26: fluctuation, fluctuating, voltage, low voltage, high voltage, up down | D26: Voltage fluctuation | E26: Electrical | F26: L031
A27: JK | B27: Jerking | C27: jerk, jerking, jhatka, jhatke, shaking | D27: (needs an object) | E27: -
A28: EN | B28: Water entering | C28: entering, coming through, coming inside, coming in, aa raha andar, ingress, getting in | D28: (needs an object) | E28: -
A29: AB | B29: Absent / sleeping | C29: absent, sleeping, not present, not on duty, sota, so raha, late, not at post | D29: (needs an object) | E29: -
A30: DS | B30: Misbehaviour / dispute | C30: rude, misbehave, misbehaviour, misbehavior, misbehaving, abusive, abusing, dispute, fight, fighting, quarrel, argument, jhagda, jhagada, badtameezi, attitude | D30: Dispute / misbehaviour | E30: Noise, Nuisance & Disputes | F30: L482
A31: DN | B31: Entry denied | C31: not allowed, denied, entry denied, roka, rok diya, refused, stopped at gate | D31: (needs an object) | E31: -
A32: NRS | B32: Not responding | C32: not responding, no response, not answering, not picking, ignoring, no reply, not replying | D32: Complaint not responded to | E32: Society Admin & Documents | F32: L483
A33: TM | B33: Timing / closed | C33: timing, timings, closed, opening time, hours, shut | D33: (needs an object) | E33: -
A34: BK | B34: Nuisance / barking | C34: barking, howling, bhok, nuisance, menace, troubling, pareshan | D34: (needs an object) | E34: -
A35: BT | B35: Biting / attacking | C35: bite, biting, bitten, attack, attacking, chasing, chase, kaata, kaat liya, aggressive | D35: (needs an object) | E35: -
A36: NCL | B36: Not collected | C36: not collected, not picked, no pickup, not taken, not lifted, nahi uthaya, collection | D36: (needs an object) | E36: -
A37: SG | B37: Not segregated | C37: not segregated, mixed, segregation | D37: (needs an object) | E37: -
A38: TH | B38: Thrown / dumped | C38: throwing, thrown, throw, threw, dumped, dumping, dump, phenk, fenk, fenka | D38: (needs an object) | E38: -
A39: OG | B39: Overgrown / not maintained | C39: overgrown, not maintained, not trimmed, untrimmed, dried, dry, not watered, sukh | D39: (needs an object) | E39: -
A40: UN | B40: Unauthorised use | C40: unauthorised, unauthorized, misuse, misused, illegal, without permission, parked, occupied, used by | D40: (needs an object) | E40: -
...

Sheet Safety Overrides
A1: Order | B1: Issue Line | C1: Category | D1: Severity | E1: Trigger words (beat everything else) | F1: Issue ID
A2: 1 | B2: Medical emergency / injury | C2: Medical & Emergency | D2: Critical | E2: ambulance, injured, injury, accident, unconscious, fainted, bleeding, heart attack, fell down, slipped, chest pain, behosh, hospital, doctor, medical emergency, chot, chot lagi | F2: L001
A3: 2 | B3: Fire / smoke | C3: Fire Safety | D3: Critical | E3: fire, aag, flames, burning, burning smell, jal raha, smoke, dhua, dhuan | F3: L002
A4: 3 | B4: Sparking / short circuit / electric shock | C4: Electrical | D4: Critical | E4: spark, sparking, short circuit, shot circuit, shock, electric shock, current lag, current laga, current lagta, live wire, exposed wire, naked wire | F4: L003
A5: 4 | B5: Person trapped in lift | C5: Lift | D5: Critical | E5: trapped, phas gaya, phasa, phansa, phans gaya, stuck inside, andar phasa | F5: L004
A6: 5 | B6: Structural collapse / danger | C6: Civil & Structural | D6: Critical | E6: collapse, collapsed, girne wala, dangerous building, building collapse | F6: L005
A7: 6 | B7: Theft / burglary | C7: Security & Gate | D7: Critical | E7: theft, stolen, chori, chor, thief, burglary, robbery, break in, steal, stealing, snatching | F7: L006
A8: 7 | B8: Child missing | C8: Security & Gate | D8: Critical | E8: child missing, missing child, kid missing, lost child, baccha missing | F8: L007
A9: 8 | B9: Harassment / threat / violence | C9: Noise, Nuisance & Disputes | D9: Critical | E9: harassment, molestation, eve teasing, stalking, threat, threatening, violence, assault | F9: L008
A10: 9 | B10: Intruder / suspicious person | C10: Security & Gate | D10: High | E10: intruder, trespasser, trespassing, stranger, suspicious, unknown person, outsider | F10: L009
A11: 10 | B11: Snake sighted | C11: Stray Animals & Pets | D11: High | E11: snake, saap, saanp, cobra | F11: L010
A12: 11 | B12: Waterlogging / flooding | C12: Drainage & Sewage | D12: High | E12: flood, flooding, flooded, waterlogging, water logging, water logged, waterlogged, pani bhar gaya | F12: L011

Sheet Locations
A1: Location | B1: Words | C1: Effect
A2: Flat | B2: flat, flats, home, house, ghar, room, bedroom, hall, living room, kitchen, bathroom, my place | C2: Recorded on the ticket only - never changes the category
A3: Balcony | B3: balcony, balconies | C3: Recorded on the ticket only - never changes the category
A4: Lobby / entrance | B4: lobby, entrance, entrance lobby, lift lobby, reception | C4: Recorded on the ticket only - never changes the category
A5: Corridor / staircase | B5: corridor, passage, gallery, staircase, stairs, stair case, sidi, landing | C5: Recorded on the ticket only - never changes the category
A6: Floor / wing / building | B6: floor, wing, tower, block, building, ground floor, top floor, upstairs, downstairs | C6: Recorded on the ticket only - never changes the category
A7: Terrace / roof | B7: terrace, roof, rooftop, podium | C7: Recorded on the ticket only - never changes the category
A8: Basement | B8: basement, stilt | C8: Recorded on the ticket only - never changes the category
A9: Compound / common area | B9: compound, premises, society, common area, campus, outside | C9: Recorded on the ticket only - never changes the category
A10: Utility rooms | B10: meter room, electric room, electrical room, panel room, pump room | C10: Recorded on the ticket only - never changes the category
A11: Society office | B11: society office, office | C11: Recorded on the ticket only - never changes the category
A13: Places that have their own facilities (clubhouse, gym, pool, play area, garden, parking) are on the Objects tab as "Place / person": any equipment named in the same message beats them, so "light not working in gym" goes to Electrical, while "gym closed" stays with Amenities.

Sheet Test Messages
A1: # | B1: Set | C1: Resident message | D1: Expected category | E1: Issue line picked | F1: Category picked | G1: Location | H1: Decided by | I1: Pass?
A2: 1 | B2: Same issue, different place | C2: AC not cooling in flat | D2: AC & Ventilation | E2: AC not cooling | F2: AC & Ventilation | G2: Flat | H2: Object + problem | I2: =IF(D2=F2,"Yes","No") -> Yes
A3: 2 | B3: Same issue, different place | C3: AC not cooling in lobby | D3: AC & Ventilation | E3: AC not cooling | F3: AC & Ventilation | G3: Lobby / entrance | H3: Object + problem | I3: =IF(D3=F3,"Yes","No") -> Yes
A4: 3 | B4: Same issue, different place | C4: Lobby AC is not cooling properly | D4: AC & Ventilation | E4: AC not cooling | F4: AC & Ventilation | G4: Lobby / entrance | H4: Object + problem | I4: =IF(D4=F4,"Yes","No") -> Yes
A5: 4 | B5: Same issue, different place | C5: Clubhouse AC not cooling | D5: AC & Ventilation | E5: AC not cooling | F5: AC & Ventilation | H5: Object + problem | I5: =IF(D5=F5,"Yes","No") -> Yes
A6: 5 | B6: Same issue, different place | C6: AC in gym not cooling | D6: AC & Ventilation | E6: AC not cooling | F6: AC & Ventilation | H6: Object + problem | I6: =IF(D6=F6,"Yes","No") -> Yes
A7: 6 | B7: Same issue, different place | C7: society office ka AC thanda nahi kar raha | D7: AC & Ventilation | E7: AC not cooling | F7: AC & Ventilation | G7: Society office | H7: Object + problem | I7: =IF(D7=F7,"Yes","No") -> Yes
A8: 7 | B8: Same issue, different place | C8: AC leaking water in corridor | D8: AC & Ventilation | E8: AC water leaking | F8: AC & Ventilation | G8: Corridor / staircase | H8: Object + problem | I8: =IF(D8=F8,"Yes","No") -> Yes
A9: 8 | B9: Same issue, different place | C9: Light not working in lobby | D9: Electrical | E9: Light not working | F9: Electrical | G9: Lobby / entrance | H9: Object + problem | I9: =IF(D9=F9,"Yes","No") -> Yes
A10: 9 | B10: Same issue, different place | C10: Light not working in gym | D10: Electrical | E10: Light not working | F10: Electrical | H10: Object + problem | I10: =IF(D10=F10,"Yes","No") -> Yes
A11: 10 | B11: Same issue, different place | C11: Light not working in parking | D11: Electrical | E11: Light not working | F11: Electrical | H11: Object + problem | I11: =IF(D11=F11,"Yes","No") -> Yes
A12: 11 | B12: Same issue, different place | C12: Tap leaking in clubhouse washroom | D12: Plumbing & Leakage | E12: Tap leaking / dripping | F12: Plumbing & Leakage | H12: Object + problem | I12: =IF(D12=F12,"Yes","No") -> Yes
A13: 12 | B13: Same issue, different place | C13: Tap leaking in my flat | D13: Plumbing & Leakage | E13: Tap leaking / dripping | F13: Plumbing & Leakage | G13: Flat | H13: Object + problem | I13: =IF(D13=F13,"Yes","No") -> Yes
A14: 13 | B14: Same issue, different place | C14: Fan not working in security cabin | D14: Electrical | E14: Fan not working | F14: Electrical | H14: Object + problem | I14: =IF(D14=F14,"Yes","No") -> Yes
A15: 14 | B15: Same issue, different place | C15: Crack in wall of terrace | D15: Civil & Structural | E15: Wall crack | F15: Civil & Structural | G15: Terrace / roof | H15: Object + problem | I15: =IF(D15=F15,"Yes","No") -> Yes
A16: 15 | B16: Same issue, different place | C16: Crack in wall of my bedroom | D16: Civil & Structural | E16: Wall crack | F16: Civil & Structural | G16: Flat | H16: Object + problem | I16: =IF(D16=F16,"Yes","No") -> Yes
A17: 16 | B17: Same issue, different place | C17: Garbage not collected from B wing | D17: Garbage & Waste | E17: Garbage not collected | F17: Garbage & Waste | G17: Floor / wing / building | H17: Object + problem | I17: =IF(D17=F17,"Yes","No") -> Yes
A18: 17 | B18: Same issue, different place | C18: Garbage not collected from clubhouse | D18: Garbage & Waste | E18: Garbage not collected | F18: Garbage & Waste | H18: Object + problem | I18: =IF(D18=F18,"Yes","No") -> Yes
A19: 18 | B19: Tuning | C19: Leakage issue in my bathroom | D19: Plumbing & Leakage | E19: Leakage (source not mentioned) | F19: Plumbing & Leakage | G19: Flat | H19: Problem only | I19: =IF(D19=F19,"Yes","No") -> Yes
A20: 19 | B20: Tuning | C20: No light in B wing since morning | D20: Electrical | E20: No electricity / power cut | F20: Electrical | G20: Floor / wing / building | H20: Object + problem | I20: =IF(D20=F20,"Yes","No") -> Yes
A21: 20 | B21: Tuning | C21: No electricity in flat 402 | D21: Electrical | E21: No electricity / power cut | F21: Electrical | G21: Flat | H21: Object + problem | I21: =IF(D21=F21,"Yes","No") -> Yes
A22: 21 | B22: Tuning | C22: light gayi hai 3rd floor pe | D22: Electrical | E22: No electricity / power cut | F22: Electrical | G22: Floor / wing / building | H22: Object + problem | I22: =IF(D22=F22,"Yes","No") -> Yes
A23: 22 | B23: Tuning | C23: Water leakage from ceiling of kitchen | D23: Plumbing & Leakage | E23: Water leakage | F23: Plumbing & Leakage | G23: Flat | H23: Object + problem | I23: =IF(D23=F23,"Yes","No") -> Yes
A24: 23 | B24: Tuning | C24: Water not coming in A-wing since 2 days | D24: Water Supply | E24: Water not coming / no water | F24: Water Supply | G24: Floor / wing / building | H24: Object + problem | I24: =IF(D24=F24,"Yes","No") -> Yes
A25: 24 | B25: Tuning | C25: pani nahi aa raha subah se | D25: Water Supply | E25: Water not coming / no water | F25: Water Supply | H25: Object + problem | I25: =IF(D25=F25,"Yes","No") -> Yes
A26: 25 | B26: Tuning | C26: Lift not working in C wing | D26: Lift | E26: Lift not working | F26: Lift | G26: Floor / wing / building | H26: Object + problem | I26: =IF(D26=F26,"Yes","No") -> Yes
A27: 26 | B27: Tuning | C27: Lift stuck between 4th and 5th floor, someone inside!! | D27: Lift | E27: Lift stuck | F27: Lift | G27: Floor / wing / building | H27: Object + problem | I27: =IF(D27=F27,"Yes","No") -> Yes
A28: 27 | B28: Tuning | C28: lift ki light band hai | D28: Lift | E28: Lift not working | F28: Lift | H28: Object + problem | I28: =IF(D28=F28,"Yes","No") -> Yes
A29: 28 | B29: Tuning | C29: Gas leakage smell near meter room | D29: Gas Supply | E29: Gas leak | F29: Gas Supply | G29: Utility rooms | H29: Object + problem | I29: =IF(D29=F29,"Yes","No") -> Yes
A30: 29 | B30: Tuning | C30: Short circuit in meter room, smoke coming | D30: Fire Safety | E30: Fire / smoke | F30: Fire Safety | G30: Utility rooms | H30: Safety override | I30: =IF(D30=F30,"Yes","No") -> Yes
A31: 30 | B31: Tuning | C31: Fire in parking area | D31: Fire Safety | E31: Fire / smoke | F31: Fire Safety | H31: Safety override | I31: =IF(D31=F31,"Yes","No") -> Yes
A32: 31 | B32: Tuning | C32: Garbage not collected today | D32: Garbage & Waste | E32: Garbage not collected | F32: Garbage & Waste | H32: Object + problem | I32: =IF(D32=F32,"Yes","No") -> Yes
A33: 32 | B33: Tuning | C33: kachra pada hai staircase me | D33: Garbage & Waste | E33: Garbage lying around | F33: Garbage & Waste | G33: Corridor / staircase | H33: Object only | I33: =IF(D33=F33,"Yes","No") -> Yes
A34: 33 | B34: Tuning | C34: Stray dogs barking all night near gate | D34: Stray Animals & Pets | E34: Dog nuisance / barking | F34: Stray Animals & Pets | H34: Object + problem | I34: =IF(D34=F34,"Yes","No") -> Yes
A35: 34 | B35: Tuning | C35: Dog bite incident near clubhouse | D35: Stray Animals & Pets | E35: Dog bite / chasing | F35: Stray Animals & Pets | H35: Object + problem | I35: =IF(D35=F35,"Yes","No") -> Yes
A36: 35 | B36: Tuning | C36: Someone parked in my parking slot | D36: Parking | E36: Someone parked in my slot | F36: Parking | H36: Object + problem | I36: =IF(D36=F36,"Yes","No") -> Yes
A37: 36 | B37: Tuning | C37: Car blocking my car since morning | D37: Parking | E37: Vehicle blocking / double parking | F37: Parking | H37: Object + problem | I37: =IF(D37=F37,"Yes","No") -> Yes
A38: 37 | B38: Tuning | C38: Watchman sleeping at night | D38: Security & Gate | E38: Security guard absent / sleeping | F38: Security & Gate | H38: Object + problem | I38: =IF(D38=F38,"Yes","No") -> Yes
A39: 38 | B39: Tuning | C39: My parcel was stolen from the lobby | D39: Security & Gate | E39: Theft / burglary | F39: Security & Gate | G39: Lobby / entrance | H39: Safety override | I39: =IF(D39=F39,"Yes","No") -> Yes
A40: 39 | B40: Tuning | C40: CCTV camera not working at main gate | D40: Security & Gate | E40: CCTV not working | F40: Security & Gate | H40: Object + problem | I40: =IF(D40=F40,"Yes","No") -> Yes
...

Sheet Old to New Map
A1: Old Category (64) | B1: Old lines | C1: Main new category | D1: Share of recognised lines | E1: Also goes to | F1: Lines not recognised
A2: Governance, AGM & Committee | B2: 813 | C2: Society Admin & Documents | D2: 0.66591928 | E2: Billing & Accounts (68), Staff & Domestic Help (21), Security & Gate (13) | F2: 367
A3: Emergency & Disaster Response | B3: 640 | C3: Fire Safety | D3: 0.20740741 | E3: Medical & Emergency (64), Gas Supply (36), Billing & Accounts (32) | F3: 235
A4: Finance, Billing & Collections | B4: 592 | C4: Billing & Accounts | D4: 0.67630058 | E4: Society Admin & Documents (63), Noise, Nuisance & Disputes (7), Parking (7) | F4: 246
A5: Maintenance Programme & Planning | B5: 556 | C5: Civil & Structural | D5: 0.13612565 | E5: Society Admin & Documents (43), Drainage & Sewage (42), Water Supply (32) | F5: 174
A6: Community, Events & Culture | B6: 521 | C6: Society Admin & Documents | D6: 0.46289753 | E6: Noise, Nuisance & Disputes (38), Billing & Accounts (17), Security & Gate (17) | F6: 238
A7: Clubhouse & Recreation | B7: 517 | C7: Amenities & Clubhouse | D7: 0.32317073 | E7: Society Admin & Documents (29), Civil & Structural (29), Billing & Accounts (26) | F7: 189
A8: Membership & Tenancy | B8: 516 | C8: Society Admin & Documents | D8: 0.68660287 | E8: Billing & Accounts (31), Security & Gate (25), Noise, Nuisance & Disputes (20) | F8: 98
A9: Electrical Systems & Wiring | B9: 440 | C9: Electrical | D9: 0.64264264 | E9: DG, Inverter & Solar (22), Internet, TV & Intercom (16), AC & Ventilation (13) | F9: 107
A10: Vendor & Contract Management | B10: 427 | C10: Society Admin & Documents | D10: 0.28099174 | E10: Billing & Accounts (41), Security & Gate (23), Renovation & Construction (13) | F10: 185
A11: Power Supply & Backup | B11: 419 | C11: Electrical | D11: 0.38421053 | E11: DG, Inverter & Solar (122), Internet, TV & Intercom (22), Fire Safety (20) | F11: 39
A12: Communication & Notices | B12: 409 | C12: Society Admin & Documents | D12: 0.49372385 | E12: Internet, TV & Intercom (45), Security & Gate (34), Civil & Structural (14) | F12: 170
A13: Security & Guard Operations | B13: 406 | C13: Security & Gate | D13: 0.49006623 | E13: Civil & Structural (31), Society Admin & Documents (31), Noise, Nuisance & Disputes (23) | F13: 104
... A64: Cyber Security & Data Privacy | B64: 39 | C64: Society Admin & Documents | D64: 0.5 | E64: Security & Gate (1), Staff & Domestic Help (1), DG, Inverter & Solar (1) | F64: 29
A65: Civil | B65: 1 | C65: Civil & Structural | D65: 1 | F65: 0
A67: Every line of the original Issue Taxonomy sheet run through the new rules. Most unrecognised lines are governance / process items (policies, audits, records) that residents rarely send on WhatsApp.

Sheet Old Lines Re-run
A1: Issue ID | B1: Issue / Problem (original) | C1: Old Category | D1: New Issue Line | E1: New Category | F1: Decided by
A2: 1 | B2: No electricity in flat | C2: Power Supply & Backup | D2: No electricity / power cut | E2: Electrical | F2: Object + problem
A3: 4 | B3: MCB tripping repeatedly | C3: Power Supply & Backup | D3: MCB tripping | E3: Electrical | F3: Object + problem
A4: 5 | B4: Fuse blown | C4: Power Supply & Backup | D4: MCB / DB - other issue | E4: Electrical | F4: Object only
A5: 6 | B5: High electricity bill | C5: Power Supply & Backup | D5: Utility bill too high / wrong | E5: Billing & Accounts | F5: Object + problem
A6: 7 | B6: Meter reading mismatch | C6: Power Supply & Backup | D6: Meter reading wrong | E6: Billing & Accounts | F6: Object + problem
A7: 8 | B7: Electricity meter not working | C7: Power Supply & Backup | D7: Electric meter not working | E7: Electrical | F7: Object + problem
A8: 12 | B8: Parking area lights not working | C8: Power Supply & Backup | D8: Light not working | E8: Electrical | F8: Object + problem
A9: 13 | B9: Electrical room fault | C9: Power Supply & Backup | D9: Electrical room fault | E9: General / Unclassified | F9: Nothing recognised
A10: 14 | B10: Transformer issue | C10: Power Supply & Backup | D10: Grid power outage (MSEDCL) | E10: Electrical | F10: Object + problem
A11: 15 | B11: Power backup not available for flats | C11: Power Supply & Backup | D11: Generator not working | E11: DG, Inverter & Solar | F11: Object + problem
A12: 17 | B12: Unauthorized power usage suspected | C12: Power Supply & Backup | D12: Power supply issue | E12: Electrical | F12: Object only
A13: 18 | B13: Power fluctuation during night | C13: Power Supply & Backup | D13: Voltage fluctuation | E13: Electrical | F13: Object + problem
... A4607: 16049 | B4607: This issue has been ongoing for a long time and needs a permanent solution. | C4607: Communication & Notices | D4607: This issue has been ongoing for a long time and needs a permanent solution. | E4607: General / Unclassified | F4607: Nothing recognised
